<?xml version="1.0" ?>


<robot name="mobile_base">
  <material name="red">
    <color rgba="0.8 0 0 1"/>
  </material>
  <material name="green">
    <color rgba="0 0.8 0 1"/>
  </material>
  <material name="blue">
    <color rgba="0 0 0.8 1"/>
  </material>
  <material name="yellow">
    <color rgba="0.8 0.8 0 1"/>
  </material>
  <material name="orange">
    <color rgba="0.8 0.25 0 1"/>
  </material>
  <material name="black">
    <color rgba="0 0 0 1"/>
  </material>
  <material name="dark_gray">
    <color rgba="0.5 0.5 0.5 1"/>
  </material>
  <material name="gray">
    <color rgba="0.753 0.753 0.753 1"/>
  </material>
  <material name="silver">
    <color rgba="0.88 0.88 0.88 1"/>
  </material>
  <material name="white">
    <color rgba="1 1 1 1"/>
  </material>
  <!-- origin mass 5 -->
  <!-- Base link -->
  <link name="base_link">
    <visual>
      <origin rpy="3.14 0 0" xyz="-0.275 0 0"/>
      <geometry>
     
        <!-- <mesh
                    filename="file:///home/simon/mobile_base_ws/src/mobile_base/urdf/base/meshes/moveo_body.dae" /> -->
        <mesh filename="file:///home/simon/SA/mobile_base_ws/src/mobile_base/urdf/base/meshes/moveo_body.dae"/>
      </geometry>
    </visual>
    <collision>
      <origin rpy="0 0 0" xyz="0 0 0"/>
      <geometry>
        <box size="0.7 0.47 0.1"/>
      </geometry>
    </collision>
    <inertial>
      <origin rpy="0 0 0" xyz="0 0 0"/>
      <mass value="20"/>
      <inertia ixx="0.38483333333333336" ixy="0.0" ixz="0.0" iyy="0.8333333333333331" iyz="0.0" izz="1.184833333333333"/>
    </inertial>
  </link>
  <!-- Robot Footprint -->
  <link name="base_footprint">
    <inertial>
      <origin rpy="1.5707963267948966 0 1.5707963267948966" xyz="0 0 0"/>
      <mass value="0"/>
      <inertia ixx="0.0" ixy="0.0" ixz="0.0" iyy="0.0" iyz="0.0" izz="0.0"/>
    </inertial>
  </link>
  <joint name="base_joint" type="fixed">
    <parent link="base_link"/>
    <child link="base_footprint"/>
    <origin rpy="0 0 0" xyz="0.0 0.0 -0.15000000000000002"/>
  </joint>
  <link name="front_right_steer_link">
    <visual>
      <origin rpy="0 0 0" xyz="0 0 0"/>
      <geometry>
        <cylinder length="0.02" radius="0.05"/>
      </geometry>
      <material name="blue"/>
    </visual>
    <collision>
      <origin rpy="0 0 0" xyz="0 0 0"/>
      <geometry>
        <cylinder length="0.02" radius="0.05"/>
      </geometry>
    </collision>
    <inertial>
      <origin rpy="0 0 0" xyz="0 0 0"/>
      <mass value="1"/>
      <inertia ixx="0.0006583333333333334" ixy="0.0" ixz="0.0" iyy="0.0006583333333333334" iyz="0.0" izz="0.0012500000000000002"/>
    </inertial>
  </link>
  <joint name="front_right_steer_joint" type="revolute">
    <parent link="base_link"/>
    <child link="front_right_steer_link"/>
    <origin rpy="0 0 0" xyz="0.27499999999999997 -0.31 0.12000000000000001"/>
    <axis xyz="0 0 1"/>
    <limit effort="10.0" lower="-0.7853981633974483" upper="0.7853981633974483" velocity="5.0"/>
  </joint>
  <link name="front_right_wheel_link">
    <visual>
      <origin rpy="0 0 0" xyz="0 0 0"/>
      <geometry>
        <cylinder length="0.05" radius="0.1"/>
      </geometry>
      <material name="red"/>
    </visual>
    <collision>
      <origin rpy="0 0 0" xyz="0 0 0"/>
      <geometry>
        <cylinder length="0.05" radius="0.1"/>
      </geometry>
    </collision>
    <inertial>
      <origin rpy="0 0 0" xyz="0 0 0"/>
      <mass value="1"/>
      <inertia ixx="0.002708333333333334" ixy="0.0" ixz="0.0" iyy="0.002708333333333334" iyz="0.0" izz="0.005000000000000001"/>
    </inertial>
  </link>
  <joint name="front_right_wheel_joint" type="continuous">
    <parent link="front_right_steer_link"/>
    <child link="front_right_wheel_link"/>
    <origin rpy="-1.5707963267948966 0 0" xyz="0 0 -0.12000000000000001"/>
    <axis xyz="0 0 1"/>
  </joint>
  <gazebo reference="front_right_steer_link">
    <material>Gazebo/Blue</material>
  </gazebo>
  <gazebo reference="front_right_wheel_link">
    <material>Gazebo/Red</material>
  </gazebo>
  <link name="front_left_steer_link">
    <visual>
      <origin rpy="0 0 0" xyz="0 0 0"/>
      <geometry>
        <cylinder length="0.02" radius="0.05"/>
      </geometry>
      <material name="blue"/>
    </visual>
    <collision>
      <origin rpy="0 0 0" xyz="0 0 0"/>
      <geometry>
        <cylinder length="0.02" radius="0.05"/>
      </geometry>
    </collision>
    <inertial>
      <origin rpy="0 0 0" xyz="0 0 0"/>
      <mass value="1"/>
      <inertia ixx="0.0006583333333333334" ixy="0.0" ixz="0.0" iyy="0.0006583333333333334" iyz="0.0" izz="0.0012500000000000002"/>
    </inertial>
  </link>
  <joint name="front_left_steer_joint" type="revolute">
    <parent link="base_link"/>
    <child link="front_left_steer_link"/>
    <origin rpy="0 0 0" xyz="0.27499999999999997 0.31 0.12000000000000001"/>
    <axis xyz="0 0 1"/>
    <limit effort="10.0" lower="-0.7853981633974483" upper="0.7853981633974483" velocity="5.0"/>
  </joint>
  <link name="front_left_wheel_link">
    <visual>
      <origin rpy="0 0 0" xyz="0 0 0"/>
      <geometry>
        <cylinder length="0.05" radius="0.1"/>
      </geometry>
      <material name="red"/>
    </visual>
    <collision>
      <origin rpy="0 0 0" xyz="0 0 0"/>
      <geometry>
        <cylinder length="0.05" radius="0.1"/>
      </geometry>
    </collision>
    <inertial>
      <origin rpy="0 0 0" xyz="0 0 0"/>
      <mass value="1"/>
      <inertia ixx="0.002708333333333334" ixy="0.0" ixz="0.0" iyy="0.002708333333333334" iyz="0.0" izz="0.005000000000000001"/>
    </inertial>
  </link>
  <joint name="front_left_wheel_joint" type="continuous">
    <parent link="front_left_steer_link"/>
    <child link="front_left_wheel_link"/>
    <origin rpy="-1.5707963267948966 0 0" xyz="0 0 -0.12000000000000001"/>
    <axis xyz="0 0 1"/>
  </joint>
  <gazebo reference="front_left_steer_link">
    <material>Gazebo/Blue</material>
  </gazebo>
  <gazebo reference="front_left_wheel_link">
    <material>Gazebo/Red</material>
  </gazebo>
  <link name="rear_right_wheel_link">
    <visual>
      <origin rpy="0 0 0" xyz="0 0 0"/>
      <geometry>
        <cylinder length="0.05" radius="0.1"/>
      </geometry>
      <material name="red"/>
    </visual>
    <collision>
      <origin rpy="0 0 0" xyz="0 0 0"/>
      <geometry>
        <cylinder length="0.05" radius="0.1"/>
      </geometry>
    </collision>
    <inertial>
      <origin rpy="0 0 0" xyz="0 0 0"/>
      <mass value="1"/>
      <inertia ixx="0.002708333333333334" ixy="0.0" ixz="0.0" iyy="0.002708333333333334" iyz="0.0" izz="0.005000000000000001"/>
    </inertial>
  </link>
  <joint name="rear_right_wheel_joint" type="continuous">
    <parent link="base_link"/>
    <child link="rear_right_wheel_link"/>
    <origin rpy="-1.5707963267948966 0 0" xyz="-0.27499999999999997 -0.31 0"/>
    <axis xyz="0 0 1"/>
  </joint>
  <gazebo reference="rear_right_wheel_link">
    <material>Gazebo/Red</material>
  </gazebo>
  <link name="rear_left_wheel_link">
    <visual>
      <origin rpy="0 0 0" xyz="0 0 0"/>
      <geometry>
        <cylinder length="0.05" radius="0.1"/>
      </geometry>
      <material name="red"/>
    </visual>
    <collision>
      <origin rpy="0 0 0" xyz="0 0 0"/>
      <geometry>
        <cylinder length="0.05" radius="0.1"/>
      </geometry>
    </collision>
    <inertial>
      <origin rpy="0 0 0" xyz="0 0 0"/>
      <mass value="1"/>
      <inertia ixx="0.002708333333333334" ixy="0.0" ixz="0.0" iyy="0.002708333333333334" iyz="0.0" izz="0.005000000000000001"/>
    </inertial>
  </link>
  <joint name="rear_left_wheel_joint" type="continuous">
    <parent link="base_link"/>
    <child link="rear_left_wheel_link"/>
    <origin rpy="-1.5707963267948966 0 0" xyz="-0.27499999999999997 0.31 0"/>
    <axis xyz="0 0 1"/>
  </joint>
  <gazebo reference="rear_left_wheel_link">
    <material>Gazebo/Red</material>
  </gazebo>
  <link name="lidar_link">
    <inertial>
      <origin rpy="0 0 0" xyz="0 0 0"/>
      <mass value="0.125"/>
      <inertia ixx="0.001" ixy="0" ixz="0" iyy="0.001" iyz="0" izz="0.001"/>
    </inertial>
    <collision>
      <origin rpy="0 0 0" xyz="0 0 0"/>
      <geometry>
        <cylinder length="0.055" radius="0.0508"/>
      </geometry>
    </collision>
    <visual>
      <origin rpy="0 0 0" xyz="0 0 0"/>
      <geometry>
        <cylinder length="0.055" radius="0.0508"/>
      </geometry>
      <material name="LightBlue">
        <color rgba="0.11 0.37 0.56 1.0"/>
      </material>
    </visual>
  </link>
  <joint name="lidar_joint" type="fixed">
    <parent link="base_link"/>
    <child link="lidar_link"/>
    <origin rpy="0 0 0" xyz="0 0 0.2"/>
  </joint>
  <gazebo reference="lidar_link">
    <sensor name="lidar" type="gpu_lidar">
      <ignition_frame_id>lidar_link</ignition_frame_id>
      <topic>scan</topic>
      <always_on>true</always_on>
      <visualize>true</visualize>
      <update_rate>5</update_rate>
      <ray>
        <scan>
          <horizontal>
            <samples>360</samples>
            <resolution>1.000000</resolution>
            <min_angle>0.000000</min_angle>
            <max_angle>6.280000</max_angle>
          </horizontal>
        </scan>
        <range>
          <min>0.120000</min>
          <max>3.5</max>
          <resolution>0.015000</resolution>
        </range>
        <noise>
          <type>gaussian</type>
          <mean>0.0</mean>
          <stddev>0.01</stddev>
        </noise>
      </ray>
    </sensor>
  </gazebo>
  <!-- IMU -->
  <link name="imu_link">
    <visual>
      <geometry>
        <box size="0.1 0.1 0.1"/>
      </geometry>
    </visual>
    <collision>
      <geometry>
        <box size="0.1 0.1 0.1"/>
      </geometry>
    </collision>
    <inertial>
      <origin rpy="1.5707963267948966 0 1.5707963267948966" xyz="0 0 0"/>
      <mass value="0.001"/>
      <inertia ixx="1.6666666666666669e-06" ixy="0.0" ixz="0.0" iyy="1.6666666666666669e-06" iyz="0.0" izz="1.6666666666666669e-06"/>
    </inertial>
  </link>
  <gazebo reference="imu_link">
    <sensor name="imu_sensor" type="imu">
      <ignition_frame_id>imu_link</ignition_frame_id>
      <plugin filename="ignition-gazebo-imu-system" name="ignition::gazebo::systems::Imu">
            </plugin>
      <topic>imu</topic>
      <always_on>true</always_on>
      <update_rate>30</update_rate>
      <visualize>true</visualize>
      <imu>
        <angular_velocity>
          <x>
            <noise type="gaussian">
              <mean>0.0</mean>
              <stddev>2e-4</stddev>
              <bias_mean>0.0000075</bias_mean>
              <bias_stddev>0.0000008</bias_stddev>
            </noise>
          </x>
          <y>
            <noise type="gaussian">
              <mean>0.0</mean>
              <stddev>2e-4</stddev>
              <bias_mean>0.0000075</bias_mean>
              <bias_stddev>0.0000008</bias_stddev>
            </noise>
          </y>
          <z>
            <noise type="gaussian">
              <mean>0.0</mean>
              <stddev>2e-4</stddev>
              <bias_mean>0.0000075</bias_mean>
              <bias_stddev>0.0000008</bias_stddev>
            </noise>
          </z>
        </angular_velocity>
        <linear_acceleration>
          <x>
            <noise type="gaussian">
              <mean>0.0</mean>
              <stddev>1.7e-2</stddev>
              <bias_mean>0.1</bias_mean>
              <bias_stddev>0.001</bias_stddev>
            </noise>
          </x>
          <y>
            <noise type="gaussian">
              <mean>0.0</mean>
              <stddev>1.7e-2</stddev>
              <bias_mean>0.1</bias_mean>
              <bias_stddev>0.001</bias_stddev>
            </noise>
          </y>
          <z>
            <noise type="gaussian">
              <mean>0.0</mean>
              <stddev>1.7e-2</stddev>
              <bias_mean>0.1</bias_mean>
              <bias_stddev>0.001</bias_stddev>
            </noise>
          </z>
        </linear_acceleration>
      </imu>
    </sensor>
  </gazebo>
  <joint name="imu_joint" type="fixed">
    <parent link="base_link"/>
    <child link="imu_link"/>
    <origin xyz="0 0 0.01"/>
  </joint>
 
<!-- </robot>

<robot name="ur10"> -->
	<link name="manipulator_base_link">
		<origin rpy="0 0 0" xyz="0 0 0"/>
		<inertial>
			<mass value="4"/>
			<inertia ixx="0.00610633" ixy="0" ixz="0" iyy="0.00610633" iyz="0" izz="0.01125"/>
		</inertial>
		<collision>
			<geometry>
				<mesh filename="file:///home/simon/SA/modi_manu_ws/install/universal_robot_ign/share/universal_robot_ign/resource/models/ur10/meshes/collision/base.stl"/>
			</geometry>
		</collision>
		<visual>
			<geometry>
				<mesh filename="file:///home/simon/SA/modi_manu_ws/install/universal_robot_ign/share/universal_robot_ign/resource/models/ur10/meshes/visual/base.dae"/>
			</geometry>
		</visual>
	</link>

    <!-- mount the manipulator_base_link to the mobile base (base_link) -->
    <joint name="mount_joint" type="fixed">
        <origin rpy="0 0 0" xyz="0 0 0.6"/>
        <parent link="base_link"/>
        <child link="manipulator_base_link"/>
    </joint>

	<joint name="shoulder_pan_joint" type="revolute">
		<origin rpy="0 -0 0" xyz="0 0 0.1273"/>
		<parent link="manipulator_base_link"/>
		<child link="shoulder_link"/>
		<axis xyz="0 0 1"/>
		<limit lower="-6.28319" upper="6.28319" effort="330" velocity="2.16"/>
		<dynamics damping="0" friction="0"/>
	</joint>
	<link name="shoulder_link">
		<origin rpy="0 -0 0" xyz="0 0 0"/>
		<inertial>
			<mass value="7.778"/>
			<inertia ixx="0.0314743" ixy="0" ixz="0" iyy="0.0314743" iyz="0" izz="0.0218756"/>
		</inertial>
		<collision>
			<geometry>
				<mesh filename="file:///home/simon/SA/modi_manu_ws/install/universal_robot_ign/share/universal_robot_ign/resource/models/ur10/meshes/collision/shoulder.stl"/>
			</geometry>
		</collision>
		<visual>
			<geometry>
				<mesh filename="file:///home/simon/SA/modi_manu_ws/install/universal_robot_ign/share/universal_robot_ign/resource/models/ur10/meshes/visual/shoulder.dae"/>
			</geometry>
		</visual>
	</link>
	<joint name="shoulder_lift_joint" type="revolute">
		<!-- <origin rpy="0 1.5708 0" xyz="0 0.220941 0"/> -->
    <origin rpy="0 0 0" xyz="0 0.220941 0"/>
		<parent link="shoulder_link"/>
		<child link="upper_arm_link"/>
		<axis xyz="0 1 0"/>
		<limit lower="-6.28319" upper="6.28319" effort="330" velocity="2.16"/>
		<dynamics damping="0" friction="0"/>
	</joint>
	<link name="upper_arm_link">
		<origin rpy="0 -0 0" xyz="0 0 0"/>
		<inertial>
			<origin rpy="0 -0 0" xyz="0 -0.045 0.306"/>
			<mass value="12.93"/>
			<inertia ixx="0.421754" ixy="0" ixz="0" iyy="0.421754" iyz="0" izz="0.0363656"/>
		</inertial>
		<collision>
			<geometry>
				<mesh filename="file:///home/simon/SA/modi_manu_ws/install/universal_robot_ign/share/universal_robot_ign/resource/models/ur10/meshes/collision/upperarm.stl"/>
			</geometry>
		</collision>
		<visual>
			<geometry>
				<mesh filename="file:///home/simon/SA/modi_manu_ws/install/universal_robot_ign/share/universal_robot_ign/resource/models/ur10/meshes/visual/upperarm.dae"/>
			</geometry>
		</visual>
	</link>
	<joint name="elbow_joint" type="revolute">
		<origin rpy="0 2.395 0" xyz="0 -0.1719 0.612"/>
		<parent link="upper_arm_link"/>
		<child link="forearm_link"/>
		<axis xyz="0 1 0"/>
		<limit lower="-3.14159" upper="3.14159" effort="150" velocity="3.15"/>
		<dynamics damping="0" friction="0"/>
	</joint>
	<link name="forearm_link">
		<origin rpy="0 -0 0" xyz="0 0 0"/>
		<inertial>
			<origin rpy="0 -0 0" xyz="0 0 0.28615"/>
			<mass value="3.87"/>
			<inertia ixx="0.11107" ixy="0" ixz="0" iyy="0.11107" iyz="0" izz="0.0108844"/>
		</inertial>
		<collision>
			<geometry>
				<mesh filename="file:///home/simon/SA/modi_manu_ws/install/universal_robot_ign/share/universal_robot_ign/resource/models/ur10/meshes/collision/forearm.stl"/>
			</geometry>
		</collision>
		<visual>
			<geometry>
				<mesh filename="file:///home/simon/SA/modi_manu_ws/install/universal_robot_ign/share/universal_robot_ign/resource/models/ur10/meshes/visual/forearm.dae"/>
			</geometry>
		</visual>
	</link>
	<joint name="wrist_1_joint" type="revolute">
		<origin rpy="0 0 0" xyz="0 0 0.5723"/>
		<parent link="forearm_link"/>
		<child link="wrist_1_link"/>
		<axis xyz="0 1 0"/>
		<limit lower="-6.28319" upper="6.28319" effort="54" velocity="3.2"/>
		<dynamics damping="0" friction="0"/>
	</joint>
	<link name="wrist_1_link">
		<origin rpy="0 -0 0" xyz="0 0 0"/>
		<inertial>
			<origin rpy="0 -0 0" xyz="0 0.1149 0"/>
			<mass value="1.96"/>
			<inertia ixx="0.00510825" ixy="0" ixz="0" iyy="0.00510825" iyz="0" izz="0.0055125"/>
		</inertial>
		<collision>
			<geometry>
				<mesh filename="file:///home/simon/SA/modi_manu_ws/install/universal_robot_ign/share/universal_robot_ign/resource/models/ur10/meshes/collision/wrist1.stl"/>
			</geometry>
		</collision>
		<visual>
			<geometry>
				<mesh filename="file:///home/simon/SA/modi_manu_ws/install/universal_robot_ign/share/universal_robot_ign/resource/models/ur10/meshes/visual/wrist1.dae"/>
			</geometry>
		</visual>
	</link>
	<joint name="wrist_2_joint" type="revolute">
		<origin rpy="0 -0 1.57079632679" xyz="0 0.1149 0"/>
		<parent link="wrist_1_link"/>
		<child link="wrist_2_link"/>
		<axis xyz="0 0 1"/>
		<limit lower="-6.28319" upper="6.28319" effort="54" velocity="3.2"/>
		<dynamics damping="0" friction="0"/>
	</joint>
	<link name="wrist_2_link">
		<origin rpy="0 -0 0" xyz="0 0 0"/>
		<inertial>
			<origin rpy="0 -0 0" xyz="0 0 0.1157"/>
			<mass value="1.96"/>
			<inertia ixx="0.00510825" ixy="0" ixz="0" iyy="0.00510825" iyz="0" izz="0.0055125"/>
		</inertial>
		<collision>
			<geometry>
				<mesh filename="file:///home/simon/SA/modi_manu_ws/install/universal_robot_ign/share/universal_robot_ign/resource/models/ur10/meshes/collision/wrist2.stl"/>
			</geometry>
		</collision>
		<visual>
			<geometry>
				<mesh filename="file:///home/simon/SA/modi_manu_ws/install/universal_robot_ign/share/universal_robot_ign/resource/models/ur10/meshes/visual/wrist2.dae"/>
			</geometry>
		</visual>
	</link>
	<joint name="wrist_3_joint" type="revolute">
		<origin rpy="0 2.441 0" xyz="0 0 0.1157"/>
		<parent link="wrist_2_link"/>
		<child link="wrist_3_link"/>
		<axis xyz="0 1 0"/>
		<limit lower="-6.28319" upper="6.28319" effort="54" velocity="3.2"/>
		<dynamics damping="0" friction="0"/>
	</joint>
	<link name="wrist_3_link">
		<origin rpy="0 -0 0" xyz="0 0 0"/>
		<inertial>
			<origin rpy="1.5708 -0 0" xyz="0 0.07695 0"/>
			<mass value="0.202"/>
			<inertia ixx="0.000117922" ixy="0" ixz="0" iyy="0.000117922" iyz="0" izz="0.000204525"/>
		</inertial>
		<collision>
			<geometry>
				<mesh filename="file:///home/simon/SA/modi_manu_ws/install/universal_robot_ign/share/universal_robot_ign/resource/models/ur10/meshes/collision/wrist3.stl"/>
			</geometry>
		</collision>
		<visual>
			<geometry>
				<mesh filename="file:///home/simon/SA/modi_manu_ws/install/universal_robot_ign/share/universal_robot_ign/resource/models/ur10/meshes/visual/wrist3.dae"/>
			</geometry>
		</visual>
	</link>
	<joint name="ee_fixed_joint" type="fixed">
		<origin rpy="0.0 0.0 1.5707963267948966" xyz="0.0 0.0922 0.0"/>
		<parent link="wrist_3_link"/>
		<child link="ee_link"/>
	</joint>
	<link name="ee_link">
		<inertial>
			<mass value="0.001"/>
			<inertia ixx="1.6666666666666667e-08" ixy="0" ixz="0" iyy="1.6666666666666667e-08" iyz="0" izz="1.6666666666666667e-08"/>
		</inertial>
		<collision>
			<geometry>
				<box size="0.01 0.01 0.01"/>
			</geometry>
		</collision>
	</link>
  <!-- <joint name="world_ur10_joint" type="fixed">
    <parent link="world"/>
		<child link="base_link"/>
  </joint> -->
     <!-- controller -->
  <ros2_control name="IgnitionSystem" type="system">
    <hardware>
      <plugin>ign_ros2_control/IgnitionSystem</plugin>
    </hardware>
    <joint name="front_left_steer_joint">
      <command_interface name="position"/>
      <state_interface name="position"/>
      <state_interface name="velocity"/>
    </joint>
    <joint name="front_right_steer_joint">
      <command_interface name="position"/>
      <state_interface name="position"/>
      <state_interface name="velocity"/>
    </joint>
    <joint name="rear_left_wheel_joint">
      <command_interface name="velocity"/>
      <state_interface name="position"/>
      <state_interface name="velocity"/>
    </joint>
    <joint name="rear_right_wheel_joint">
      <command_interface name="velocity"/>
      <state_interface name="position"/>
      <state_interface name="velocity"/>
    </joint>
    <joint name="front_left_wheel_joint">
      <state_interface name="position"/>
      <state_interface name="velocity"/>
    </joint>
    <joint name="front_right_wheel_joint">
      <state_interface name="position"/>
      <state_interface name="velocity"/>
    </joint>

    <joint name="shoulder_pan_joint">
      <command_interface name="position"/>
      <command_interface name="velocity"/>
      <state_interface name="position"/>
      <state_interface name="velocity"/>
    </joint>
    <joint name="shoulder_lift_joint">
      <command_interface name="position"/>
      <command_interface name="velocity"/>
      <state_interface name="position"/>
      <state_interface name="velocity"/>
    </joint>
    <joint name="elbow_joint">
      <command_interface name="position"/>
      <command_interface name="velocity"/>
      <state_interface name="position"/>
      <state_interface name="velocity"/>
    </joint>
    <joint name="wrist_1_joint">
      <command_interface name="position"/>
      <command_interface name="velocity"/>
      <state_interface name="position"/>
      <state_interface name="velocity"/>
    </joint>
    <joint name="wrist_2_joint">
      <command_interface name="position"/>
      <command_interface name="velocity"/>
      <state_interface name="position"/>
      <state_interface name="velocity"/>
    </joint>
    <joint name="wrist_3_joint">
      <command_interface name="position"/>
      <command_interface name="velocity"/>
      <state_interface name="position"/>
      <state_interface name="velocity"/>
    </joint>
  </ros2_control>
  <gazebo>
    <plugin filename="ign_ros2_control-system" name="ign_ros2_control::IgnitionROS2ControlPlugin">
      <ros>
        <namespace/>
        <remapping>ackermann_steering_controller/reference_unstamped:=cmd_vel</remapping>
        <remapping>ackermann_steering_controller/odometry:=ackodom</remapping>
        <remapping>ackermann_steering_controller/tf_odometry:=tf</remapping>
      </ros>
      <parameters>/home/simon/SA/mobile_manipulator/install/mobile_base/share/mobile_base/config/ackermann_steering_controller.yaml</parameters>
    </plugin>
  </gazebo>
</robot>